# 04 Gerenciando erros na aplicação

Agora, adicionaremos a lógica dentro do interceptor para que possamos capturar possíveis erros, verificar o tipo de erro e fornecer feedback para pessoa usuária. Como já criamos o interceptor, precisamos registrá-lo. Faremos isso dentro de `app.module.ts`.

Abrindo esse arquivo, selecionaremos o código que temos dentro de `providers`, nas últimas linhas do arquivo, e pressionaremos "Alt + Shift + ↓", copiando esse código para as linhas abaixo. Além disso, após o fechamento de chaves do primeiro interceptor, adicionaremos uma vírgula. No novo código, o `provide` continuará sendo a classe `HTTP_ INTERCEPTORS`, mas `useClass` será o novo `ErrosInterceptor`. Concluído, já o importamos.

```typescript
// código omitido

providers: [
    {
    provide: HTTP_INTERCEPTORS,
    useClass: AutenticacaoInterceptor,
    multi: true
    },
    {
    provide: HTTP_INTERCEPTORS,
    useClass: ErrosInterceptor,
    multi: true
    }
],
```

Agora, posso fechar o `app.module.ts` e retornar para o `erros.interceptor.ts`. No `intercept()`, recebemos como parâmetro a requisição e o manipulador. Vamos tipar esses dois parâmetros. Para isso, selecionamos o `unknown` do `request`, pressionamos "Ctrl + D" para selecionar o `unknow` do `next` também, e escreveremos `HTTPErrorResponse` como o tipo.

```typescript
//código omitido

intercept (
    request: HttpRequest<HttpErrorResponse>,
    next: HttpHandler): Observable<HttpEvent<HttpErrorResponse>> {
        return next.handle(request);
    })
```

Como o retorno desse método `intercept()` é um `Observable`, vou utilizaremos alguns operadores do RxJS para manipularmos essa requisição. Sendo assim, no final do `return` adicionaremos um `.pipe()` fazermos o encadeamento dos operadores do RxJS. Usaremos `catchError()`, porque queremos capturar um erro. Nos parênteses, receberemos o `error: HTTPErrorResponse`. Criaremos uma arrow function para continuarmos adicionando a lógica.

```typescript
//código omitido

intercept (
    request: HttpRequest<HttpErrorResponse>,
    next: HttpHandler): Observable<HttpEvent<HttpErrorResponse>> {
        return next.handle(request).pipe(
            catchError((error: HttpErrorResponse) => {
                
        });
    })
```

Precisamos retornar esse erro no final, então, antes de fechar chaves, escreveremos `return throwError()`, que é outro operador do RxJS. Nos parênteses, escreveremos outra arrow function, passando um `new Error ('Ops, ocorreu um erro!')`, ou seja, passamos a mensagem de erro.

```typescript
//código omitido

intercept (
    request: HttpRequest<HttpErrorResponse>,
    next: HttpHandler): Observable<HttpEvent<HttpErrorResponse>> {
        return next.handle(request).pipe(
            catchError((error: HttpErrorResponse) => {
                
                return throwError (() => new Error('Ops, ocorreu um erro!'));
        });
    })
```

Agora, adicionaremos a lógica dentro do `catchError()`. Começamos criando uma variável local que vai conter uma mensagem de texto que será mostrada para a pessoa usuária. Para isso codamos `let errorMessage = 'Ocorreu um erro desconhecido`.

Então deixamos a mensagem padrão "Ocorreu um erro desconhecido", isso porque não vamos verificar todos os status de erro, mas utilizaremos alguns que fazem mais sentido para a aplicação. Caso nenhum desses erros verificados ocorra, a mensagem padrão que ficará é "Ocorreu um erro desconhecido".

```typescript
//código omitido

return next.handle(request).pipe(
    catchError((error: HttpErrorResponse) => {
        let errorMessage = 'Ocorreu um erro desconhecido';
        
        return throwError (() => new Error('Ops, ocorreu um erro!'));
});
```

Agora, faremos uma verificação do tipo de erro. Primeiro, verificaremos se o erro está acontecendo do lado da pessoa cliente ou do servidor. Para isso, na linha abaixo do `errorMessage`, escreveremos um `if()` e verificaremos o tipo do erro. Se `error.error` for uma instância de `ErrorEvent`, isso indica que esse erro está acontecendo do lado do cliente, e não é um erro do tipo `httpErrorResponse`. Nesses casos, a mensagem que aparecerá será `` `Erro do cliente: ${error.error.message}'` ``.

```typescript
//código omitido

return next.handle(request).pipe(
    catchError((error: HttpErrorResponse) => {
        let errorMessage = 'Ocorreu um erro desconhecido';
        
        if (error.error instanceof ErrorEvent) {
            errorMessage = `Erro do cliente: ${error.error.message}`;
        }
        
        return throwError (() => new Error('Ops, ocorreu um erro!'));
});
```

Caso não seja um erro do lado do cliente, verificaremos o status de erro do servidor. Então, após o fechamento de chaves do `if()`, adicionaremos um `else if(error.status === 404)` para verificarmos o status 404. Se for esse erro, a `errorMessage` será "Recurso não encontrado".

```typescript
//código omitido

return next.handle(request).pipe(
    catchError((error: HttpErrorResponse) => {
        let errorMessage = 'Ocorreu um erro desconhecido';
        
        if (error.error instanceof ErrorEvent) {
            errorMessage = `Erro do cliente: ${error.error.message}`;
        } else if (error.status === 404) {
            errorMessage = 'Recurso não encontrado';
        
        return throwError (() => new Error('Ops, ocorreu um erro!'));
});
```

Além do erro 404, verificaremos os status de erro `500`, que é um erro do servidor, e `401`, para acesso não autorizado. As mensagens serão, sucessivamente, "Erro interno no servidor" e "Você não está autorizado a acessar este recurso". Caso não caia em nenhuma dessas condições, a mensagem padrão será "Ocorreu um erro desconhecido".

```typescript
return next.handle(request).pipe(
    catchError((error: HttpErrorResponse) => {
        let errorMessage = 'Ocorreu um erro desconhecido';

        if (error.error instanceof ErrorEvent) {
            // Erro do lado do cliente, como uma rede interrompida
            errorMessage = `Erro do cliente: ${error.error.message}`;
        } else if (error.status === 404) {
            // Recurso não encontrado (erro 404)
            errorMessage = 'Recurso não encontrado';
        } else if (error.status === 500) {
            // Erro interno do servidor (erro 500)
            errorMessage = 'Erro interno do servidor';
        } else if (error.status === 401) {
            // Não autorizado (erro 401)
            errorMessage = 'Você não está autorizado a acessar este recurso';
        }
        
        console.error( error);
        console.error(errorMessage);
        
        return throwError (() => new Error('Ops, ocorreu um erro!'));
    });
```

Para visualizarmos se isso está funcionando, adicionamos um `console.error(error)` e um `console.error(errorMessage)`, para recebermos o erro e a mensgem. Agora, vamos simular um erro para testar se o interceptor está funcionando.

No menu Explorer, na lateral esquerda do VS Code, dentro acessaremos "core > `unidade-federativa.service.ts`. No método `requestEstados()` , mais ao final do código, excluiremos duas letras de `/estados`, deixando como `/estad`.

```typescript
//código omitido
private requestEstados(): Observable<UnidadeFederativa[]> {
    return this.http.get<UnidadeFederativa[]>(`${this.apiUrl}/estad`);
}
```

De volta à aplicação, abriremos o console, onde observamos o erro "Recurso não encontrado" e o status 404. Isso indica que o interceptor já está funcionando, mas ainda precisamos fornecer um feedback visual para o usuário, que será implementado em breve.