Considere a seguinte implementação de um sistema de compras: uma função recebe um _array_ de itens para processar a compra. Caso não seja passado um parâmetro com os itens, é lançada uma exceção. Aqui está o código que exemplifica esse comportamento:

```javascript
finalizaCompra(itens) {
    if (itens === undefined){
    throw new Error(‘Sem itens na compra’);
}
// Resto do código
};
```

Agora, digamos que você é o responsável por escrever os testes dessa função. Quais alternativas contém um teste que captura o erro lançado?

- Alternativa correta
    
    [ ] 
    
    ```javascript
    test('Deve lançar erro caso não receba parâmetros', () => {
    function englobaErro() {
    finalizaCompra();
    }
    expect(englobaErro).toThrowError('Sem itens na compra');
    }
    ```
    
    Esse teste cria uma função nomeada que é passada como parâmetro no `expect`, que, por sua vez, faz a asserção se um erro é lançado.
    
- Alternativa incorreta
    
    ```bash
    test('Deve lançar erro caso não receba parâmetros', () => {
    expect(finalizaCompra()).toThrowError('Sem itens na compra');
    }
    ```
    
    No parâmetro da chamada à `expect` foi colocada a execução da função que queremos testar, fazendo com que durante o teste a exceção seja lançada sem ser capturada.
    
- Alternativa correta
    
    ```javascript
    test('Deve lançar erro caso não receba parâmetros', () => {
    expect(() => {
        finalizaCompra();
    }).toThrowError('Sem itens na compra');
    }
    ```
    
    Esse teste cria uma _arrow function_ dentro da chamada do `expect` no primeiro parâmetro e em seguida faz a asserção se um erro é lançado.
    
- Alternativa incorreta
    
    ```javascript
    test('Deve lançar erro caso não receba parâmetros', () => {
    const resultado = finalizaCompra();
    expect(resultado).toThrowError('Sem itens na compra');
    }
    ```
    
    Ao chamar a função `finalizaCompra()` estaremos executando ela e lançando a exceção, interrompendo a execução do teste.
    

Parabéns, você acertou!